<sdf version='1.4'>
  <world name='default'>
    <light name='sun' type='directional'>
      <cast_shadows>1</cast_shadows>
      <pose>0 0 10 0 -0 0</pose>
      <diffuse>0.8 0.8 0.8 1</diffuse>
      <specular>0.2 0.2 0.2 1</specular>
      <attenuation>
        <range>1000</range>
        <constant>0.9</constant>
        <linear>0.01</linear>
        <quadratic>0.001</quadratic>
      </attenuation>
      <direction>-0.5 0.1 -0.9</direction>
    </light>
    <model name='ground_plane'>
      <static>1</static>
      <link name='link'>
        <collision name='collision'>
          <geometry>
            <plane>
              <normal>0 0 1</normal>
              <size>100 100</size>
            </plane>
          </geometry>
          <surface>
            <friction>
              <ode>
                <mu>100</mu>
                <mu2>50</mu2>
              </ode>
            </friction>
            <bounce/>
            <contact>
              <ode/>
            </contact>
          </surface>
          <max_contacts>10</max_contacts>
        </collision>
        <visual name='visual'>
          <cast_shadows>0</cast_shadows>
          <geometry>
            <plane>
              <normal>0 0 1</normal>
              <size>100 100</size>
            </plane>
          </geometry>
          <material>
            <script>
              <uri>file://media/materials/scripts/gazebo.material</uri>
              <name>Gazebo/Grey</name>
            </script>
          </material>
        </visual>
        <velocity_decay>
          <linear>0</linear>
          <angular>0</angular>
        </velocity_decay>
        <self_collide>0</self_collide>
        <kinematic>0</kinematic>
        <gravity>1</gravity>
      </link>
    </model>
    <physics type='ode'>
      <max_step_size>0.001</max_step_size>
      <real_time_factor>1</real_time_factor>
      <real_time_update_rate>1000</real_time_update_rate>
      <gravity>0 0 -9.8</gravity>
    </physics>
    <scene>
      <ambient>0.4 0.4 0.4 1</ambient>
      <background>0.7 0.7 0.7 1</background>
      <shadows>1</shadows>
    </scene>
    <spherical_coordinates>
      <surface_model>EARTH_WGS84</surface_model>
      <latitude_deg>0</latitude_deg>
      <longitude_deg>0</longitude_deg>
      <elevation>0</elevation>
      <heading_deg>0</heading_deg>
    </spherical_coordinates>
    <model name='mobile_base'>
      <link name='base_link'>
        <pose>0 0 0 0 -0 0</pose>
        <inertial>
          <pose>-0.0853273 -0.000842446 0.102267 0 -0 0</pose>
          <mass>33.755</mass>
          <inertia>
            <ixx>0.932632</ixx>
            <ixy>-0.0237012</ixy>
            <ixz>-0.14409</ixz>
            <iyy>2.08972</iyy>
            <iyz>-0.00162353</iyz>
            <izz>2.35029</izz>
          </inertia>
        </inertial>
        <collision name='base_link_collision'>
          <pose>0 0 0.061875 0 -0 0</pose>
          <geometry>
            <box>
              <size>0.9874 0.5709 0.12375</size>
            </box>
          </geometry>
          <max_contacts>10</max_contacts>
          <surface>
            <bounce/>
            <friction>
              <ode/>
            </friction>
            <contact>
              <ode/>
            </contact>
          </surface>
        </collision>
        <collision name='base_link_collision_base_link_1'>
          <pose>0 0 0.185625 0 -0 0</pose>
          <geometry>
            <box>
              <size>0.78992 0.5709 0.12375</size>
            </box>
          </geometry>
          <max_contacts>10</max_contacts>
          <surface>
            <bounce/>
            <friction>
              <ode/>
            </friction>
            <contact>
              <ode/>
            </contact>
          </surface>
        </collision>
        <collision name='base_link_collision_top_plate_link'>
          <pose>0.0812 0 0.245 0 -0 0</pose>
          <geometry>
            <mesh>
              <scale>1 1 1</scale>
              <uri>/home/arunabh/MPC_ROS/ros_ws/src/husky/husky_description/meshes/top_plate.dae</uri>
            </mesh>
          </geometry>
          <max_contacts>10</max_contacts>
          <surface>
            <bounce/>
            <friction>
              <ode/>
            </friction>
            <contact>
              <ode/>
            </contact>
          </surface>
        </collision>
        <collision name='base_link_collision_top_plate_link_1'>
          <pose>0.0812 0 0.245 0 -0 0</pose>
          <geometry>
            <box>
              <size>0.32 0.41 0.09</size>
            </box>
          </geometry>
          <max_contacts>10</max_contacts>
          <surface>
            <bounce/>
            <friction>
              <ode/>
            </friction>
            <contact>
              <ode/>
            </contact>
          </surface>
        </collision>
        <collision name='base_link_collision_velodyne_base_link'>
          <pose>0.0812 0 0.39195 0 -0 0</pose>
          <geometry>
            <cylinder>
              <length>0.0717</length>
              <radius>0.0516</radius>
            </cylinder>
          </geometry>
          <max_contacts>10</max_contacts>
          <surface>
            <bounce/>
            <friction>
              <ode/>
            </friction>
            <contact>
              <ode/>
            </contact>
          </surface>
        </collision>
        <visual name='base_link_visual'>
          <pose>0 0 0 0 -0 0</pose>
          <geometry>
            <mesh>
              <scale>1 1 1</scale>
              <uri>/home/arunabh/MPC_ROS/ros_ws/src/husky/husky_description/meshes/base_link.dae</uri>
            </mesh>
          </geometry>
        </visual>
        <visual name='base_link_visual_front_bumper_link'>
          <pose>0.48 0 0.091 0 -0 0</pose>
          <geometry>
            <mesh>
              <scale>1 1 1</scale>
              <uri>/home/arunabh/MPC_ROS/ros_ws/src/husky/husky_description/meshes/bumper.dae</uri>
            </mesh>
          </geometry>
        </visual>
        <visual name='base_link_visual_rear_bumper_link'>
          <pose>-0.48 0 0.091 0 -0 3.14159</pose>
          <geometry>
            <mesh>
              <scale>1 1 1</scale>
              <uri>/home/arunabh/MPC_ROS/ros_ws/src/husky/husky_description/meshes/bumper.dae</uri>
            </mesh>
          </geometry>
        </visual>
        <visual name='base_link_visual_top_chassis_link'>
          <pose>0 0 0 0 -0 0</pose>
          <geometry>
            <mesh>
              <scale>1 1 1</scale>
              <uri>/home/arunabh/MPC_ROS/ros_ws/src/husky/husky_description/meshes/top_chassis.dae</uri>
            </mesh>
          </geometry>
        </visual>
        <visual name='base_link_visual_top_plate_link'>
          <pose>0.0812 0 0.245 0 -0 0</pose>
          <geometry>
            <mesh>
              <scale>1 1 1</scale>
              <uri>/home/arunabh/MPC_ROS/ros_ws/src/husky/husky_description/meshes/top_plate.dae</uri>
            </mesh>
          </geometry>
        </visual>
        <visual name='base_link_visual_user_rail_link'>
          <pose>0.272 0 0.245 0 -0 0</pose>
          <geometry>
            <mesh>
              <scale>1 1 1</scale>
              <uri>/home/arunabh/MPC_ROS/ros_ws/src/husky/husky_description/meshes/user_rail.dae</uri>
            </mesh>
          </geometry>
        </visual>
        <visual name='base_link_visual_velodyne'>
          <pose>0.0812 0 0.3561 0 -0 0</pose>
          <geometry>
            <mesh>
              <scale>1 1 1</scale>
              <uri>/home/arunabh/MPC_ROS/ros_ws/src/husky/husky_description/meshes/accessories/VLP16_scan.dae</uri>
            </mesh>
          </geometry>
        </visual>
        <visual name='base_link_visual_velodyne_base_link'>
          <pose>0.0812 0 0.3561 0 -0 0</pose>
          <geometry>
            <mesh>
              <scale>1 1 1</scale>
              <uri>/home/arunabh/MPC_ROS/ros_ws/src/husky/husky_description/meshes/accessories/VLP16_base_1.dae</uri>
            </mesh>
          </geometry>
        </visual>
        <visual name='base_link_visual_velodyne_base_link_1'>
          <pose>0.0812 0 0.3561 0 -0 0</pose>
          <geometry>
            <mesh>
              <scale>1 1 1</scale>
              <uri>/home/arunabh/MPC_ROS/ros_ws/src/husky/husky_description/meshes/accessories/VLP16_base_2.dae</uri>
            </mesh>
          </geometry>
        </visual>
        <visual name='base_link_visual_vlp16_mount'>
          <pose>0.0812 0 0.245 0 -0 0</pose>
          <geometry>
            <cylinder>
              <length>0.34</length>
              <radius>0.0416</radius>
            </cylinder>
          </geometry>
          <material>
            <script>
              <name>Gazebo/Grey</name>
              <uri>__default__</uri>
            </script>
          </material>
        </visual>
        <velocity_decay>
          <linear>0</linear>
          <angular>0</angular>
        </velocity_decay>
        <velocity_decay>
          <linear>0</linear>
          <angular>0</angular>
        </velocity_decay>
        <gravity>1</gravity>
        <velocity_decay>
          <linear>0</linear>
          <angular>0</angular>
        </velocity_decay>
        <self_collide>0</self_collide>
        <sensor name='velodyne-VLP16' type='ray'>
          <visualize>0</visualize>
          <update_rate>10</update_rate>
          <ray>
            <scan>
              <horizontal>
                <samples>500</samples>
                <resolution>1</resolution>
                <min_angle>-3.14159</min_angle>
                <max_angle>3.14159</max_angle>
              </horizontal>
              <vertical>
                <samples>16</samples>
                <resolution>1</resolution>
                <min_angle>-0.261799</min_angle>
                <max_angle>0.261799</max_angle>
              </vertical>
            </scan>
            <range>
              <min>0.3</min>
              <max>131</max>
              <resolution>0.001</resolution>
            </range>
            <noise>
              <type>gaussian</type>
              <mean>0</mean>
              <stddev>0</stddev>
            </noise>
          </ray>
          <plugin name='gazebo_ros_laser_controller' filename='libgazebo_ros_velodyne_laser.so'>
            <topicName>/velodyne_points</topicName>
            <frameName>velodyne</frameName>
            <min_range>0.9</min_range>
            <max_range>130.0</max_range>
            <gaussianNoise>0.008</gaussianNoise>
            <robotNamespace>/</robotNamespace>
          </plugin>
          <pose>0.0812 0 0.3938 0 -0 0</pose>
        </sensor>
        <kinematic>0</kinematic>
      </link>
      <link name='front_left_wheel_link'>
        <pose>0.256 0.2854 0.03282 0 -0 0</pose>
        <inertial>
          <pose>0 0 0 0 -0 0</pose>
          <mass>2.637</mass>
          <inertia>
            <ixx>0.02467</ixx>
            <ixy>0</ixy>
            <ixz>0</ixz>
            <iyy>0.02467</iyy>
            <iyz>0</iyz>
            <izz>0.04411</izz>
          </inertia>
        </inertial>
        <collision name='front_left_wheel_link_collision'>
          <pose>0 0 0 1.57079 -0 0</pose>
          <geometry>
            <cylinder>
              <length>0.1143</length>
              <radius>0.17775</radius>
            </cylinder>
          </geometry>
          <surface>
            <contact>
              <ode>
                <kp>1e+07</kp>
                <kd>1</kd>
              </ode>
            </contact>
            <friction>
              <ode>
                <mu>1</mu>
                <mu2>1</mu2>
                <fdir1>1 0 0</fdir1>
              </ode>
            </friction>
            <bounce/>
          </surface>
          <max_contacts>10</max_contacts>
        </collision>
        <visual name='front_left_wheel_link_visual'>
          <pose>0 0 0 0 -0 0</pose>
          <geometry>
            <mesh>
              <scale>1 1 1</scale>
              <uri>/home/arunabh/MPC_ROS/ros_ws/src/husky/husky_description/meshes/wheel.dae</uri>
            </mesh>
          </geometry>
        </visual>
        <gravity>1</gravity>
        <velocity_decay>
          <linear>0</linear>
          <angular>0</angular>
        </velocity_decay>
        <self_collide>0</self_collide>
        <kinematic>0</kinematic>
      </link>
      <joint name='front_left_wheel' type='revolute'>
        <child>front_left_wheel_link</child>
        <parent>base_link</parent>
        <axis>
          <xyz>0 1 0</xyz>
          <limit>
            <lower>-1e+16</lower>
            <upper>1e+16</upper>
          </limit>
          <dynamics/>
        </axis>
      </joint>
      <link name='front_right_wheel_link'>
        <pose>0.256 -0.2854 0.03282 0 -0 0</pose>
        <inertial>
          <pose>0 0 0 0 -0 0</pose>
          <mass>2.637</mass>
          <inertia>
            <ixx>0.02467</ixx>
            <ixy>0</ixy>
            <ixz>0</ixz>
            <iyy>0.02467</iyy>
            <iyz>0</iyz>
            <izz>0.04411</izz>
          </inertia>
        </inertial>
        <collision name='front_right_wheel_link_collision'>
          <pose>0 0 0 1.57079 -0 0</pose>
          <geometry>
            <cylinder>
              <length>0.1143</length>
              <radius>0.17775</radius>
            </cylinder>
          </geometry>
          <surface>
            <contact>
              <ode>
                <kp>1e+07</kp>
                <kd>1</kd>
              </ode>
            </contact>
            <friction>
              <ode>
                <mu>1</mu>
                <mu2>1</mu2>
                <fdir1>1 0 0</fdir1>
              </ode>
            </friction>
            <bounce/>
          </surface>
          <max_contacts>10</max_contacts>
        </collision>
        <visual name='front_right_wheel_link_visual'>
          <pose>0 0 0 0 -0 0</pose>
          <geometry>
            <mesh>
              <scale>1 1 1</scale>
              <uri>/home/arunabh/MPC_ROS/ros_ws/src/husky/husky_description/meshes/wheel.dae</uri>
            </mesh>
          </geometry>
        </visual>
        <gravity>1</gravity>
        <velocity_decay>
          <linear>0</linear>
          <angular>0</angular>
        </velocity_decay>
        <self_collide>0</self_collide>
        <kinematic>0</kinematic>
      </link>
      <joint name='front_right_wheel' type='revolute'>
        <child>front_right_wheel_link</child>
        <parent>base_link</parent>
        <axis>
          <xyz>0 1 0</xyz>
          <limit>
            <lower>-1e+16</lower>
            <upper>1e+16</upper>
          </limit>
          <dynamics/>
        </axis>
      </joint>
      <link name='rear_left_wheel_link'>
        <pose>-0.256 0.2854 0.03282 0 -0 0</pose>
        <inertial>
          <pose>0 0 0 0 -0 0</pose>
          <mass>2.637</mass>
          <inertia>
            <ixx>0.02467</ixx>
            <ixy>0</ixy>
            <ixz>0</ixz>
            <iyy>0.02467</iyy>
            <iyz>0</iyz>
            <izz>0.04411</izz>
          </inertia>
        </inertial>
        <collision name='rear_left_wheel_link_collision'>
          <pose>0 0 0 1.57079 -0 0</pose>
          <geometry>
            <cylinder>
              <length>0.1143</length>
              <radius>0.17775</radius>
            </cylinder>
          </geometry>
          <surface>
            <contact>
              <ode>
                <kp>1e+07</kp>
                <kd>1</kd>
              </ode>
            </contact>
            <friction>
              <ode>
                <mu>1</mu>
                <mu2>1</mu2>
                <fdir1>1 0 0</fdir1>
              </ode>
            </friction>
            <bounce/>
          </surface>
          <max_contacts>10</max_contacts>
        </collision>
        <visual name='rear_left_wheel_link_visual'>
          <pose>0 0 0 0 -0 0</pose>
          <geometry>
            <mesh>
              <scale>1 1 1</scale>
              <uri>/home/arunabh/MPC_ROS/ros_ws/src/husky/husky_description/meshes/wheel.dae</uri>
            </mesh>
          </geometry>
        </visual>
        <gravity>1</gravity>
        <velocity_decay>
          <linear>0</linear>
          <angular>0</angular>
        </velocity_decay>
        <self_collide>0</self_collide>
        <kinematic>0</kinematic>
      </link>
      <joint name='rear_left_wheel' type='revolute'>
        <child>rear_left_wheel_link</child>
        <parent>base_link</parent>
        <axis>
          <xyz>0 1 0</xyz>
          <limit>
            <lower>-1e+16</lower>
            <upper>1e+16</upper>
          </limit>
          <dynamics/>
        </axis>
      </joint>
      <link name='rear_right_wheel_link'>
        <pose>-0.256 -0.2854 0.03282 0 -0 0</pose>
        <inertial>
          <pose>0 0 0 0 -0 0</pose>
          <mass>2.637</mass>
          <inertia>
            <ixx>0.02467</ixx>
            <ixy>0</ixy>
            <ixz>0</ixz>
            <iyy>0.02467</iyy>
            <iyz>0</iyz>
            <izz>0.04411</izz>
          </inertia>
        </inertial>
        <collision name='rear_right_wheel_link_collision'>
          <pose>0 0 0 1.57079 -0 0</pose>
          <geometry>
            <cylinder>
              <length>0.1143</length>
              <radius>0.17775</radius>
            </cylinder>
          </geometry>
          <surface>
            <contact>
              <ode>
                <kp>1e+07</kp>
                <kd>1</kd>
              </ode>
            </contact>
            <friction>
              <ode>
                <mu>1</mu>
                <mu2>1</mu2>
                <fdir1>1 0 0</fdir1>
              </ode>
            </friction>
            <bounce/>
          </surface>
          <max_contacts>10</max_contacts>
        </collision>
        <visual name='rear_right_wheel_link_visual'>
          <pose>0 0 0 0 -0 0</pose>
          <geometry>
            <mesh>
              <scale>1 1 1</scale>
              <uri>/home/arunabh/MPC_ROS/ros_ws/src/husky/husky_description/meshes/wheel.dae</uri>
            </mesh>
          </geometry>
        </visual>
        <gravity>1</gravity>
        <velocity_decay>
          <linear>0</linear>
          <angular>0</angular>
        </velocity_decay>
        <self_collide>0</self_collide>
        <kinematic>0</kinematic>
      </link>
      <joint name='rear_right_wheel' type='revolute'>
        <child>rear_right_wheel_link</child>
        <parent>base_link</parent>
        <axis>
          <xyz>0 1 0</xyz>
          <limit>
            <lower>-1e+16</lower>
            <upper>1e+16</upper>
          </limit>
          <dynamics/>
        </axis>
      </joint>
      <plugin name='gazebo_ros_control' filename='libgazebo_ros_control.so'>
        <robotNamespace>/</robotNamespace>
      </plugin>
      <static>0</static>
      <plugin name='imu_controller' filename='libhector_gazebo_ros_imu.so'>
        <robotNamespace>/</robotNamespace>
        <updateRate>50.0</updateRate>
        <bodyName>base_link</bodyName>
        <topicName>imu/data</topicName>
        <accelDrift>0.005 0.005 0.005</accelDrift>
        <accelGaussianNoise>0.005 0.005 0.005</accelGaussianNoise>
        <rateDrift>0.005 0.005 0.005</rateDrift>
        <rateGaussianNoise>0.005 0.005 0.005</rateGaussianNoise>
        <headingDrift>0.005</headingDrift>
        <headingGaussianNoise>0.005</headingGaussianNoise>
      </plugin>
      <pose>0 0 0 0 -0 0</pose>
    </model>
    <state world_name='default'>
      <sim_time>2253 678000000</sim_time>
      <real_time>704 352949444</real_time>
      <wall_time>1509490674 961824201</wall_time>
      <model name='bookshelf'>
        <pose>11 -1 0 0 -0 0</pose>
        <link name='link'>
          <pose>11 -1 0 0 -0 0</pose>
          <velocity>0 0 0 0 -0 0</velocity>
          <acceleration>0 0 0 0 -0 0</acceleration>
          <wrench>0 0 0 0 -0 0</wrench>
        </link>
      </model>
      <model name='grey_wall'>
        <pose>3.50081 2 0 0 -0 0</pose>
        <link name='link'>
          <pose>3.50081 2 1.4 0 -0 0</pose>
          <velocity>0 0 0 0 -0 0</velocity>
          <acceleration>0 0 0 0 -0 0</acceleration>
          <wrench>0 0 0 0 -0 0</wrench>
        </link>
      </model>
      <model name='grey_wall_0'>
        <pose>11 2 0 0 -0 0</pose>
        <link name='link'>
          <pose>11 2 1.4 0 -0 0</pose>
          <velocity>0 0 0 0 -0 0</velocity>
          <acceleration>0 0 0 0 -0 0</acceleration>
          <wrench>0 0 0 0 -0 0</wrench>
        </link>
      </model>
      <model name='grey_wall_1'>
        <pose>3.69238 -2.03683 0 0 -0 0</pose>
        <link name='link'>
          <pose>3.69238 -2.03683 1.4 0 -0 0</pose>
          <velocity>0 0 0 0 -0 0</velocity>
          <acceleration>0 0 0 0 -0 0</acceleration>
          <wrench>0 0 0 0 -0 0</wrench>
        </link>
      </model>
      <model name='grey_wall_2'>
        <pose>11 -2 0 0 -0 0</pose>
        <link name='link'>
          <pose>11 -2 1.4 0 -0 0</pose>
          <velocity>0 0 0 0 -0 0</velocity>
          <acceleration>0 0 0 0 -0 0</acceleration>
          <wrench>0 0 0 0 -0 0</wrench>
        </link>
      </model>
      <model name='ground_plane'>
        <pose>0 0 0 0 -0 0</pose>
        <link name='link'>
          <pose>0 0 0 0 -0 0</pose>
          <velocity>0 0 0 0 -0 0</velocity>
          <acceleration>0 0 0 0 -0 0</acceleration>
          <wrench>0 0 0 0 -0 0</wrench>
        </link>
      </model>
      <model name='mobile_base'>
        <pose>10.8152 -0.170907 0.144929 5.29396e-23 -1e-06 0.85225</pose>
        <link name='base_link'>
          <pose>10.8152 -0.170907 0.144929 5.29396e-23 -1e-06 0.85225</pose>
          <velocity>0.001346 0.008844 6e-06 6.6e-05 -0.000139 0.963055</velocity>
          <acceleration>0 0 0 0 -0 0</acceleration>
          <wrench>0 0 0 0 -0 0</wrench>
        </link>
        <link name='front_left_wheel_link'>
          <pose>10.7689 0.209678 0.177749 -3.14152 -1.46056 -2.28941</pose>
          <velocity>-0.365207 -0.035564 2.3e-05 -1.02934 -1.29293 -2.17864</velocity>
          <acceleration>0 0 0 0 -0 0</acceleration>
          <wrench>0 0 0 0 -0 0</wrench>
        </link>
        <link name='front_right_wheel_link'>
          <pose>11.1986 -0.166075 0.177749 8e-06 -0.253982 0.852248</pose>
          <velocity>-0.003113 0.378067 6.2e-05 0.96124 1.23321 -2.17852</velocity>
          <acceleration>0 0 0 0 -0 0</acceleration>
          <wrench>0 0 0 0 -0 0</wrench>
        </link>
        <link name='rear_left_wheel_link'>
          <pose>10.4319 -0.175738 0.177748 -3.14153 -1.45925 -2.2894</pose>
          <velocity>0.005844 -0.360332 -5e-05 -1.02949 -1.29275 -2.17851</velocity>
          <acceleration>0 0 0 0 -0 0</acceleration>
          <wrench>0 0 0 0 -0 0</wrench>
        </link>
        <link name='rear_right_wheel_link'>
          <pose>10.8615 -0.551491 0.177749 8e-06 -0.246935 0.852248</pose>
          <velocity>0.367908 0.0533 -1.3e-05 0.96126 1.23319 -2.17852</velocity>
          <acceleration>0 0 0 0 -0 0</acceleration>
          <wrench>0 0 0 0 -0 0</wrench>
        </link>
      </model>
      <model name='person_standing_0'>
        <pose>4.55722 -0.480831 -0 -1e-06 1e-06 -0.000879</pose>
        <link name='link'>
          <pose>4.55722 -0.480831 -0 -1e-06 1e-06 -0.000879</pose>
          <velocity>0 0 0 0 -0 0</velocity>
          <acceleration>0 0 0 0 -0 0</acceleration>
          <wrench>0 0 0 0 -0 0</wrench>
        </link>
      </model>
      <model name='person_standing_1'>
        <pose>9.00005 1 0 0 1e-06 -0.000481</pose>
        <link name='link'>
          <pose>9.00005 1 0 0 1e-06 -0.000481</pose>
          <velocity>0 0 0 0 -0 0</velocity>
          <acceleration>0 0 0 0 -0 0</acceleration>
          <wrench>0 0 0 0 -0 0</wrench>
        </link>
      </model>
    </state>
    <gui fullscreen='0'>
      <camera name='user_camera'>
        <pose>9.78685 0.261248 8.74331 8.7056e-16 1.5698 -3.13499</pose>
        <view_controller>orbit</view_controller>
      </camera>
    </gui>
    <model name='grey_wall'>
      <static>1</static>
      <link name='link'>
        <pose>0 0 1.4 0 -0 0</pose>
        <collision name='collision'>
          <geometry>
            <box>
              <size>7.5 0.2 2.8</size>
            </box>
          </geometry>
          <max_contacts>10</max_contacts>
          <surface>
            <bounce/>
            <friction>
              <ode/>
            </friction>
            <contact>
              <ode/>
            </contact>
          </surface>
        </collision>
        <visual name='visual'>
          <cast_shadows>0</cast_shadows>
          <geometry>
            <box>
              <size>7.5 0.2 2.8</size>
            </box>
          </geometry>
          <material>
            <script>
              <uri>model://grey_wall/materials/scripts</uri>
              <uri>model://grey_wall/materials/textures</uri>
              <name>vrc/grey_wall</name>
            </script>
          </material>
        </visual>
        <velocity_decay>
          <linear>0</linear>
          <angular>0</angular>
        </velocity_decay>
        <self_collide>0</self_collide>
        <kinematic>0</kinematic>
        <gravity>1</gravity>
      </link>
      <pose>3.50081 2 0 0 -0 0</pose>
    </model>
    <model name='grey_wall_0'>
      <static>1</static>
      <link name='link'>
        <pose>0 0 1.4 0 -0 0</pose>
        <collision name='collision'>
          <geometry>
            <box>
              <size>7.5 0.2 2.8</size>
            </box>
          </geometry>
          <max_contacts>10</max_contacts>
          <surface>
            <bounce/>
            <friction>
              <ode/>
            </friction>
            <contact>
              <ode/>
            </contact>
          </surface>
        </collision>
        <visual name='visual'>
          <cast_shadows>0</cast_shadows>
          <geometry>
            <box>
              <size>7.5 0.2 2.8</size>
            </box>
          </geometry>
          <material>
            <script>
              <uri>model://grey_wall/materials/scripts</uri>
              <uri>model://grey_wall/materials/textures</uri>
              <name>vrc/grey_wall</name>
            </script>
          </material>
        </visual>
        <velocity_decay>
          <linear>0</linear>
          <angular>0</angular>
        </velocity_decay>
        <self_collide>0</self_collide>
        <kinematic>0</kinematic>
        <gravity>1</gravity>
      </link>
      <pose>11 2 0 0 -0 0</pose>
    </model>
    <model name='grey_wall_1'>
      <static>1</static>
      <link name='link'>
        <pose>0 0 1.4 0 -0 0</pose>
        <collision name='collision'>
          <geometry>
            <box>
              <size>7.5 0.2 2.8</size>
            </box>
          </geometry>
          <max_contacts>10</max_contacts>
          <surface>
            <bounce/>
            <friction>
              <ode/>
            </friction>
            <contact>
              <ode/>
            </contact>
          </surface>
        </collision>
        <visual name='visual'>
          <cast_shadows>0</cast_shadows>
          <geometry>
            <box>
              <size>7.5 0.2 2.8</size>
            </box>
          </geometry>
          <material>
            <script>
              <uri>model://grey_wall/materials/scripts</uri>
              <uri>model://grey_wall/materials/textures</uri>
              <name>vrc/grey_wall</name>
            </script>
          </material>
        </visual>
        <velocity_decay>
          <linear>0</linear>
          <angular>0</angular>
        </velocity_decay>
        <self_collide>0</self_collide>
        <kinematic>0</kinematic>
        <gravity>1</gravity>
      </link>
      <pose>3 -2 0 0 -0 0</pose>
    </model>
    <model name='grey_wall_2'>
      <static>1</static>
      <link name='link'>
        <pose>0 0 1.4 0 -0 0</pose>
        <collision name='collision'>
          <geometry>
            <box>
              <size>7.5 0.2 2.8</size>
            </box>
          </geometry>
          <max_contacts>10</max_contacts>
          <surface>
            <bounce/>
            <friction>
              <ode/>
            </friction>
            <contact>
              <ode/>
            </contact>
          </surface>
        </collision>
        <visual name='visual'>
          <cast_shadows>0</cast_shadows>
          <geometry>
            <box>
              <size>7.5 0.2 2.8</size>
            </box>
          </geometry>
          <material>
            <script>
              <uri>model://grey_wall/materials/scripts</uri>
              <uri>model://grey_wall/materials/textures</uri>
              <name>vrc/grey_wall</name>
            </script>
          </material>
        </visual>
        <velocity_decay>
          <linear>0</linear>
          <angular>0</angular>
        </velocity_decay>
        <self_collide>0</self_collide>
        <kinematic>0</kinematic>
        <gravity>1</gravity>
      </link>
      <pose>11 -2 0 0 -0 0</pose>
    </model>
    <model name='person_standing_0'>
      <link name='link'>
        <inertial>
          <pose>0 -0.1 0.95 0 -0 0</pose>
          <mass>80</mass>
          <inertia>
            <ixx>24.88</ixx>
            <ixy>0</ixy>
            <ixz>0</ixz>
            <iyy>25.73</iyy>
            <iyz>0</iyz>
            <izz>2.48</izz>
          </inertia>
        </inertial>
        <collision name='bottom'>
          <pose>0 -0.1 0.01 0 -0 0</pose>
          <geometry>
            <box>
              <size>0.5 0.35 0.02</size>
            </box>
          </geometry>
          <max_contacts>10</max_contacts>
          <surface>
            <bounce/>
            <friction>
              <ode/>
            </friction>
            <contact>
              <ode/>
            </contact>
          </surface>
        </collision>
        <collision name='person'>
          <pose>0 0 0.02 0.04 -0 0</pose>
          <geometry>
            <mesh>
              <uri>model://person_standing/meshes/standing.dae</uri>
            </mesh>
          </geometry>
          <max_contacts>10</max_contacts>
          <surface>
            <bounce/>
            <friction>
              <ode/>
            </friction>
            <contact>
              <ode/>
            </contact>
          </surface>
        </collision>
        <visual name='visual'>
          <pose>0 0 0.02 0.04 -0 0</pose>
          <geometry>
            <mesh>
              <uri>model://person_standing/meshes/standing.dae</uri>
            </mesh>
          </geometry>
        </visual>
        <velocity_decay>
          <linear>0</linear>
          <angular>0</angular>
        </velocity_decay>
        <self_collide>0</self_collide>
        <kinematic>0</kinematic>
        <gravity>1</gravity>
      </link>
      <pose>4.55713 -0.480831 0 0 -0 0</pose>
      <static>0</static>
    </model>
    <model name='person_standing_1'>
      <link name='link'>
        <inertial>
          <pose>0 -0.1 0.95 0 -0 0</pose>
          <mass>80</mass>
          <inertia>
            <ixx>24.88</ixx>
            <ixy>0</ixy>
            <ixz>0</ixz>
            <iyy>25.73</iyy>
            <iyz>0</iyz>
            <izz>2.48</izz>
          </inertia>
        </inertial>
        <collision name='bottom'>
          <pose>0 -0.1 0.01 0 -0 0</pose>
          <geometry>
            <box>
              <size>0.5 0.35 0.02</size>
            </box>
          </geometry>
          <max_contacts>10</max_contacts>
          <surface>
            <bounce/>
            <friction>
              <ode/>
            </friction>
            <contact>
              <ode/>
            </contact>
          </surface>
        </collision>
        <collision name='person'>
          <pose>0 0 0.02 0.04 -0 0</pose>
          <geometry>
            <mesh>
              <uri>model://person_standing/meshes/standing.dae</uri>
            </mesh>
          </geometry>
          <max_contacts>10</max_contacts>
          <surface>
            <bounce/>
            <friction>
              <ode/>
            </friction>
            <contact>
              <ode/>
            </contact>
          </surface>
        </collision>
        <visual name='visual'>
          <pose>0 0 0.02 0.04 -0 0</pose>
          <geometry>
            <mesh>
              <uri>model://person_standing/meshes/standing.dae</uri>
            </mesh>
          </geometry>
        </visual>
        <velocity_decay>
          <linear>0</linear>
          <angular>0</angular>
        </velocity_decay>
        <self_collide>0</self_collide>
        <kinematic>0</kinematic>
        <gravity>1</gravity>
      </link>
      <pose>9 1 0 0 -0 0</pose>
      <static>0</static>
    </model>
    <model name='bookshelf'>
      <static>1</static>
      <link name='link'>
        <inertial>
          <mass>1</mass>
        </inertial>
        <collision name='back'>
          <pose>0 0.005 0.6 0 -0 0</pose>
          <geometry>
            <box>
              <size>0.9 0.01 1.2</size>
            </box>
          </geometry>
          <max_contacts>10</max_contacts>
          <surface>
            <bounce/>
            <friction>
              <ode/>
            </friction>
            <contact>
              <ode/>
            </contact>
          </surface>
        </collision>
        <visual name='visual1'>
          <pose>0 0.005 0.6 0 -0 0</pose>
          <geometry>
            <box>
              <size>0.9 0.01 1.2</size>
            </box>
          </geometry>
          <material>
            <script>
              <uri>file://media/materials/scripts/gazebo.material</uri>
              <name>Gazebo/Wood</name>
            </script>
          </material>
        </visual>
        <collision name='left_side'>
          <pose>0.45 -0.195 0.6 0 -0 0</pose>
          <geometry>
            <box>
              <size>0.02 0.4 1.2</size>
            </box>
          </geometry>
          <max_contacts>10</max_contacts>
          <surface>
            <bounce/>
            <friction>
              <ode/>
            </friction>
            <contact>
              <ode/>
            </contact>
          </surface>
        </collision>
        <visual name='visual2'>
          <pose>0.45 -0.195 0.6 0 -0 0</pose>
          <geometry>
            <box>
              <size>0.02 0.4 1.2</size>
            </box>
          </geometry>
          <material>
            <script>
              <uri>file://media/materials/scripts/gazebo.material</uri>
              <name>Gazebo/Wood</name>
            </script>
          </material>
        </visual>
        <collision name='right_side'>
          <pose>-0.45 -0.195 0.6 0 -0 0</pose>
          <geometry>
            <box>
              <size>0.02 0.4 1.2</size>
            </box>
          </geometry>
          <max_contacts>10</max_contacts>
          <surface>
            <bounce/>
            <friction>
              <ode/>
            </friction>
            <contact>
              <ode/>
            </contact>
          </surface>
        </collision>
        <visual name='visual3'>
          <pose>-0.45 -0.195 0.6 0 -0 0</pose>
          <geometry>
            <box>
              <size>0.02 0.4 1.2</size>
            </box>
          </geometry>
          <material>
            <script>
              <uri>file://media/materials/scripts/gazebo.material</uri>
              <name>Gazebo/Wood</name>
            </script>
          </material>
        </visual>
        <collision name='bottom'>
          <pose>0 -0.195 0.03 0 -0 0</pose>
          <geometry>
            <box>
              <size>0.88 0.4 0.06</size>
            </box>
          </geometry>
          <max_contacts>10</max_contacts>
          <surface>
            <bounce/>
            <friction>
              <ode/>
            </friction>
            <contact>
              <ode/>
            </contact>
          </surface>
        </collision>
        <visual name='visual4'>
          <pose>0 -0.195 0.03 0 -0 0</pose>
          <geometry>
            <box>
              <size>0.88 0.4 0.06</size>
            </box>
          </geometry>
          <material>
            <script>
              <uri>file://media/materials/scripts/gazebo.material</uri>
              <name>Gazebo/Wood</name>
            </script>
          </material>
        </visual>
        <collision name='top'>
          <pose>0 -0.195 1.19 0 -0 0</pose>
          <geometry>
            <box>
              <size>0.88 0.4 0.02</size>
            </box>
          </geometry>
          <max_contacts>10</max_contacts>
          <surface>
            <bounce/>
            <friction>
              <ode/>
            </friction>
            <contact>
              <ode/>
            </contact>
          </surface>
        </collision>
        <visual name='visual5'>
          <pose>0 -0.195 1.19 0 -0 0</pose>
          <geometry>
            <box>
              <size>0.88 0.4 0.02</size>
            </box>
          </geometry>
          <material>
            <script>
              <uri>file://media/materials/scripts/gazebo.material</uri>
              <name>Gazebo/Wood</name>
            </script>
          </material>
        </visual>
        <collision name='low_shelf'>
          <pose>0 -0.195 0.43 0 -0 0</pose>
          <geometry>
            <box>
              <size>0.88 0.4 0.02</size>
            </box>
          </geometry>
          <max_contacts>10</max_contacts>
          <surface>
            <bounce/>
            <friction>
              <ode/>
            </friction>
            <contact>
              <ode/>
            </contact>
          </surface>
        </collision>
        <visual name='visual6'>
          <pose>0 -0.195 0.43 0 -0 0</pose>
          <geometry>
            <box>
              <size>0.88 0.4 0.02</size>
            </box>
          </geometry>
          <material>
            <script>
              <uri>file://media/materials/scripts/gazebo.material</uri>
              <name>Gazebo/Wood</name>
            </script>
          </material>
        </visual>
        <collision name='high_shelf'>
          <pose>0 -0.195 0.8 0 -0 0</pose>
          <geometry>
            <box>
              <size>0.88 0.4 0.02</size>
            </box>
          </geometry>
          <max_contacts>10</max_contacts>
          <surface>
            <bounce/>
            <friction>
              <ode/>
            </friction>
            <contact>
              <ode/>
            </contact>
          </surface>
        </collision>
        <visual name='visual7'>
          <pose>0 -0.195 0.8 0 -0 0</pose>
          <geometry>
            <box>
              <size>0.88 0.4 0.02</size>
            </box>
          </geometry>
          <material>
            <script>
              <uri>file://media/materials/scripts/gazebo.material</uri>
              <name>Gazebo/Wood</name>
            </script>
          </material>
        </visual>
        <velocity_decay>
          <linear>0</linear>
          <angular>0</angular>
        </velocity_decay>
        <self_collide>0</self_collide>
        <kinematic>0</kinematic>
        <gravity>1</gravity>
      </link>
      <pose>11 -1 0 0 -0 0</pose>
    </model>
  </world>
</sdf>
